Workbook

Sheet Importacion
B2: NOXA LIVING — Análisis de Importación desde China
B3: Dispensador Automático de Jabón · FOB Guangdong / Shenzhen → Colombia
B5: Texto azul = celda editable | HS Code sugerido: 8424.89.00 (verificar con agente de aduanas)
B7: A. PARÁMETROS BASE (todos editables)
B8: TRM — Tasa de Cambio (USD → COP) | C8: 4200 | D8: Verificar en Banco de la República antes de ordenar.
B9: Precio FOB por unidad (USD) | C9: 8 | D9: Ex-factory China. Editar con cotización confirmada.
B10: Número de unidades a importar | C10: 25 | D10: Lote inicial. Ver hoja "Volumen" para comparar escalas.
B11: Peso estimado por unidad (kg) | C11: 0.8 | D11: Incluye unidad + empaque original del fabricante.
B12: Dimensiones (largo x ancho x alto) cm | C12: 20x15x15 | D12: Para calcular peso volumétrico aéreo (÷5000).
B13: FOB Total (USD) | C13: =C9*C10 | D13: =unidades × precio FOB
B14: FOB Total (COP) | C14: =C13*C8 | D14: =FOB USD × TRM
B16: B. FLETE INTERNACIONAL (China → Puerto Colombia)
B17: Flete marítimo LCL — Guangdong a Cartagena (USD) | C17: 600 | D17: Costo mínimo LCL incluye: océano + THC origen + BL + handling destino.
B18: Recargo combustible / seguridad (USD) | C18: 80 | D18: Aprox. 12-15% del flete base. Varía con precio del petróleo.
B19: Seguro de carga internacional (% sobre FOB) | C19: 0.005 | D19: 0.5% sobre valor FOB. Obligatorio para cubrir pérdida/daño.
B20: Seguro en USD (calculado) | C20: =C13*C19 | D20: =FOB Total × % seguro
B21: VALOR CIF TOTAL (USD) — base para aranceles | C21: =C13+C17+C18+C20 | D21: CIF = FOB + Flete + Recargo + Seguro
B22: VALOR CIF POR UNIDAD (USD) | C22: =IFERROR(C21/C10,0) | D22: =CIF Total / unidades
B24: C. ARANCELES E IMPUESTOS DE IMPORTACIÓN (DIAN Colombia)
B25: Arancel NMF — China sin TLC (% sobre CIF) | C25: 0.15 | D25: HS 8424.89.00 aprox. 15%. Confirmar con agente de aduanas DIAN.
B26: IVA de importación (% sobre CIF + Arancel) | C26: 0.19 | D26: 19% fijo en Colombia. Base = CIF + Arancel.
B27: Arancel total (USD) | C27: =C21*C25 | D27: =CIF × % arancel
B28: Base gravable IVA (USD) = CIF + Arancel | C28: =C21+C27
B29: IVA de importación (USD) | C29: =C28*C26 | D29: =Base gravable × 19%
B30: TOTAL IMPUESTOS (USD) | C30: =C27+C29 | D30: Arancel + IVA
B31: TOTAL IMPUESTOS (COP) | C31: =C30*C8 | D31: =USD × TRM
B33: D. GASTOS LOCALES EN COLOMBIA (COP)
B34: Agente de aduanas (honorarios) | C34: 300000 | D34: Trámite Declaración de Importación ante DIAN.
B35: Gastos portuarios — terminal y handling | C35: 180000 | D35: Cartagena o Buenaventura. Varía por terminal.
B36: Transporte: puerto → bodega Bogotá | C36: 250000 | D36: Carga de aprox. 20-25 kg. Editar si otra ciudad.
B37: VUCE / Vistos Buenos (si aplica) | C37: 80000 | D37: Solo si el producto requiere permiso previo de entidad.
B38: Otros gastos / imprevistos (COP) | C38: 100000 | D38: Reserva del 5-10% para gastos inesperados.
B39: TOTAL GASTOS LOCALES (COP) | C39: =SUM(C34:C38)
B41: E. COSTO DE ATERRIZAJE TOTAL (Landed Cost)
B42: FOB total (COP) | C42: =C14
B43: Flete + recargo + seguro (COP) | C43: =(C17+C18+C20)*C8
B44: Aranceles + IVA (COP) | C44: =C31
B45: Gastos locales (COP) | C45: =C39
B46: COSTO ATERRIZAJE TOTAL (COP) | C46: =SUM(C42:C45)
B47: COSTO POR UNIDAD (COP) | C47: =IFERROR(C46/C10,0) | D47: ← Este es tu costo real puesto en bodega
...

Sheet Aereo_vs_Maritimo
B2: COMPARATIVA: FLETE AÉREO vs. MARÍTIMO — 25 unidades
B3: Costos base importados de hoja "Importacion". Solo varía el flete.
B5: Concepto | C5: Aéreo (7-15 días) | D5: Marítimo (35-50 días)
B6: FOB total (25 u. x $8 USD — COP) | C6: =Importacion!C14 | D6: =Importacion!C14
B7: Flete internacional (USD) | C7: 350 | D7: 600
B8: Recargo combustible y seguridad (USD) | C8: 60 | D8: 80
B9: Seguro de carga (USD) | C9: =Importacion!C20 | D9: =Importacion!C20
B10: CIF Total (USD) | C10: =Importacion!C13+C7+C8+C9 | D10: =Importacion!C13+D7+D8+D9
B11: Arancel 15% sobre CIF (COP) | C11: =C10*Importacion!$C$8*Importacion!$C$25 | D11: =D10*Importacion!$C$8*Importacion!$C$25
B12: Base gravable IVA (USD) | C12: =C10*(1+Importacion!$C$25) | D12: =D10*(1+Importacion!$C$25)
B13: IVA 19% sobre base gravable (COP) | C13: =C12*Importacion!$C$8*Importacion!$C$26 | D13: =D12*Importacion!$C$8*Importacion!$C$26
B14: Flete + recargo + seguro convertido (COP) | C14: =(C7+C8+C9)*Importacion!$C$8 | D14: =(D7+D8+D9)*Importacion!$C$8
B15: Gastos locales Colombia (COP) | C15: =Importacion!C39 | D15: =Importacion!C39
B17: COSTO TOTAL ATERRIZAJE (COP) | C17: AÉREO | D17: MARÍTIMO
B18: Total COP | C18: =C6+(C7+C8+C9)*Importacion!$C$8+C11+C13+Importacion!C39 | D18: =D6+(D7+D8+D9)*Importacion!$C$8+D11+D13+Importacion!C39
B19: COSTO POR UNIDAD (COP) | C19: =IFERROR(C18/Importacion!$C$10,0) | D19: =IFERROR(D18/Importacion!$C$10,0)
B20: Tiempo de entrega estimado | C20: 7 – 15 días | D20: 35 – 50 días
B22: RECOMENDACION: Para 25 unidades, la diferencia entre aéreo y marítimo es pequeña. Prefiere flete aéreo en el primer pedido — llegas 5 semanas antes al mercado.

Sheet Volumen
B2: COSTO POR UNIDAD SEGÚN VOLUMEN DE PEDIDO (Flete marítimo)
B3: El flete marítimo tiene un costo fijo mínimo — a mayor volumen, menor costo por unidad.
B5: Unidades | C5: FOB Total (USD) | D5: Flete+Imp. (COP) | E5: Local (COP) | F5: Costo/unidad (COP) | G5: Margen a $139,900
B6: 25 | C6: 200 | D6: 4219524 | E6: 910000 | F6: 238781 | G6: -0.92359734
B7: 50 | C7: 400 | D7: 4932950 | E7: 910000 | F7: 150459 | G7: -0.2922754
B8: 100 | C8: 800 | D8: 6417281 | E8: 910000 | F8: 106873 | G8: 0.019277141
B9: 200 | C9: 1600 | D9: 8811172 | E9: 910000 | F9: 82206 | G9: 0.19559558
B10: 500 | C10: 4000 | D10: 16567614 | E10: 910000 | F10: 68555 | G10: 0.29316978
B13: Amarillo = lote inicial 25 u. Verde = punto de eficiencia (100+ u.) Flete marítimo estimado incluye: LCL + THC origen/destino + BL + seguro + handling.
